2025-01-21T20:42:33 {"block_run_id": 331, "block_uuid": "data_evaluator", "pipeline_run_id": 36, "pipeline_schedule_id": 30, "pipeline_uuid": "real_estate", "hostname": "72754110c32d", "block_type": "custom", "level": "INFO", "message": "Start executing block with BlockExecutor.", "timestamp": 1737492153.578007, "uuid": "42177b0b824f4ddfa157a4a8f2382b9c"}
2025-01-21T20:42:33 {"block_run_id": 331, "block_uuid": "data_evaluator", "pipeline_run_id": 36, "pipeline_schedule_id": 30, "pipeline_uuid": "real_estate", "hostname": "72754110c32d", "block_type": "custom", "level": "INFO", "message": "Delaying execution by 10 seconds...", "timestamp": 1737492153.974513, "uuid": "eeb615312e664f009f60274f691edd57"}
2025-01-21T20:42:43 {"block_run_id": 331, "block_uuid": "data_evaluator", "pipeline_run_id": 36, "pipeline_schedule_id": 30, "pipeline_uuid": "real_estate", "hostname": "72754110c32d", "block_type": "custom", "level": "INFO", "message": "Resuming execution after delay.", "timestamp": 1737492163.984716, "uuid": "ecba915eb87f48a7aca510c3489db28c"}
2025-01-21T20:42:44 {"block_run_id": 331, "block_uuid": "data_evaluator", "pipeline_run_id": 36, "pipeline_schedule_id": 30, "pipeline_uuid": "real_estate", "hostname": "72754110c32d", "block_type": "custom", "level": "INFO", "message": "Postgres initialized", "timestamp": 1737492164.003949, "uuid": "b8634203ad8842a58371fdcbf761caeb"}
2025-01-21T20:42:44 {"block_run_id": 331, "block_uuid": "data_evaluator", "pipeline_run_id": 36, "pipeline_schedule_id": 30, "pipeline_uuid": "real_estate", "hostname": "72754110c32d", "block_type": "custom", "level": "INFO", "message": "\u2514\u2500 Opening connection to PostgreSQL database...", "timestamp": 1737492164.004436, "uuid": "467a16601cce41b89bd00c08d99f7fd5"}
2025-01-21T20:42:44 {"block_run_id": 331, "block_uuid": "data_evaluator", "pipeline_run_id": 36, "pipeline_schedule_id": 30, "pipeline_uuid": "real_estate", "hostname": "72754110c32d", "block_type": "custom", "level": "INFO", "message": "DONE", "timestamp": 1737492164.02008, "uuid": "b7b2372dd1074dad8f1d656cda17c0d5"}
2025-01-21T20:42:44 {"block_run_id": 331, "block_uuid": "data_evaluator", "pipeline_run_id": 36, "pipeline_schedule_id": 30, "pipeline_uuid": "real_estate", "hostname": "72754110c32d", "block_type": "custom", "level": "INFO", "message": "", "timestamp": 1737492164.02047, "uuid": "4ec92a2aedd34af7b9be548d840aa2ac"}
2025-01-21T20:42:44 {"block_run_id": 331, "block_uuid": "data_evaluator", "pipeline_run_id": 36, "pipeline_schedule_id": 30, "pipeline_uuid": "real_estate", "hostname": "72754110c32d", "block_type": "custom", "level": "INFO", "message": "\u251c\u2500", "timestamp": 1737492164.020775, "uuid": "d6874a6befab4401b204cac41908f76d"}
2025-01-21T20:42:44 {"block_run_id": 331, "block_uuid": "data_evaluator", "pipeline_run_id": 36, "pipeline_schedule_id": 30, "pipeline_uuid": "real_estate", "hostname": "72754110c32d", "block_type": "custom", "level": "INFO", "message": "\u2514\u2500 Loading data with query", "timestamp": 1737492164.021026, "uuid": "d53648e4de6d4101b9562763dcd444d3"}
2025-01-21T20:42:44 {"block_run_id": 331, "block_uuid": "data_evaluator", "pipeline_run_id": 36, "pipeline_schedule_id": 30, "pipeline_uuid": "real_estate", "hostname": "72754110c32d", "block_type": "custom", "level": "INFO", "message": "", "timestamp": 1737492164.021288, "uuid": "e013b7f417894200ad5fe9fe1605f1b0"}
2025-01-21T20:42:44 {"block_run_id": 331, "block_uuid": "data_evaluator", "pipeline_run_id": 36, "pipeline_schedule_id": 30, "pipeline_uuid": "real_estate", "hostname": "72754110c32d", "block_type": "custom", "level": "INFO", "message": "SELECT * FROM public.real_estate_data_weekly;", "timestamp": 1737492164.021521, "uuid": "ed9bdc2c3c10402bb4e9702143a82812"}
2025-01-21T20:42:44 {"block_run_id": 331, "block_uuid": "data_evaluator", "pipeline_run_id": 36, "pipeline_schedule_id": 30, "pipeline_uuid": "real_estate", "hostname": "72754110c32d", "block_type": "custom", "level": "INFO", "message": "", "timestamp": 1737492164.021801, "uuid": "bc8595c686524d70b71330ef924ba083"}
2025-01-21T20:42:44 {"block_run_id": 331, "block_uuid": "data_evaluator", "pipeline_run_id": 36, "pipeline_schedule_id": 30, "pipeline_uuid": "real_estate", "hostname": "72754110c32d", "block_type": "custom", "level": "INFO", "message": "...", "timestamp": 1737492164.02201, "uuid": "0daf2e9e722249e19950ad5e74103a0a"}
2025-01-21T20:42:44 {"block_run_id": 331, "block_uuid": "data_evaluator", "pipeline_run_id": 36, "pipeline_schedule_id": 30, "pipeline_uuid": "real_estate", "hostname": "72754110c32d", "block_type": "custom", "level": "WARNING", "message": "Exception thrown when attempting to run <function BlockExecutor.execute.<locals>.__execute_with_retry at 0x7f677ed38670>, attempt 1 of 1", "timestamp": 1737492164.023831, "uuid": "e49e96fb848841c48172309ca7ca01a4", "error": "Traceback (most recent call last):\n  File \"/usr/local/lib/python3.10/site-packages/pandas/io/sql.py\", line 2018, in execute\n    cur.execute(*args, **kwargs)\npsycopg2.errors.UndefinedTable: relation \"public.real_estate_data_weekly\" does not exist\nLINE 3:     SELECT * FROM public.real_estate_data_weekly\n                          ^\n\n\nThe above exception was the direct cause of the following exception:\n\nTraceback (most recent call last):\n  File \"/usr/local/lib/python3.10/site-packages/mage_ai/shared/retry.py\", line 38, in retry_func\n    return func(*args, **kwargs)\n  File \"/usr/local/lib/python3.10/site-packages/mage_ai/data_preparation/executors/block_executor.py\", line 621, in __execute_with_retry\n    return self._execute(\n  File \"/usr/local/lib/python3.10/site-packages/mage_ai/data_preparation/executors/block_executor.py\", line 1154, in _execute\n    result = self.block.execute_sync(\n  File \"/usr/local/lib/python3.10/site-packages/mage_ai/data_preparation/models/block/__init__.py\", line 1691, in execute_sync\n    return __execute()\n  File \"/usr/local/lib/python3.10/site-packages/mage_ai/data_preparation/models/block/__init__.py\", line 1668, in __execute\n    raise err\n  File \"/usr/local/lib/python3.10/site-packages/mage_ai/data_preparation/models/block/__init__.py\", line 1570, in __execute\n    output = self.execute_block(\n  File \"/usr/local/lib/python3.10/site-packages/mage_ai/data_preparation/models/block/__init__.py\", line 1910, in execute_block\n    outputs = self._execute_block(\n  File \"/usr/local/lib/python3.10/site-packages/mage_ai/data_preparation/models/block/__init__.py\", line 2073, in _execute_block\n    outputs = self.execute_block_function(\n  File \"/usr/local/lib/python3.10/site-packages/mage_ai/data_preparation/models/block/__init__.py\", line 2169, in execute_block_function\n    output = block_function_updated(*input_vars, **global_vars)\n  File \"<string>\", line 90, in transform_custom\n  File \"/usr/local/lib/python3.10/site-packages/mage_ai/io/sql.py\", line 214, in load\n    return read_sql(\n  File \"/usr/local/lib/python3.10/site-packages/pandas/io/sql.py\", line 564, in read_sql\n    return pandas_sql.read_query(\n  File \"/usr/local/lib/python3.10/site-packages/pandas/io/sql.py\", line 2078, in read_query\n    cursor = self.execute(*args)\n  File \"/usr/local/lib/python3.10/site-packages/pandas/io/sql.py\", line 2030, in execute\n    raise ex from exc\npandas.errors.DatabaseError: Execution failed on sql '\nWITH subquery AS (\n    SELECT * FROM public.real_estate_data_weekly\n)\n\nSELECT *\nFROM subquery\nLIMIT 10000000\n': relation \"public.real_estate_data_weekly\" does not exist\nLINE 3:     SELECT * FROM public.real_estate_data_weekly\n                          ^\n\n", "error_stack": ["  File \"/usr/local/bin/mage\", line 8, in <module>\n    sys.exit(app())\n", "  File \"/usr/local/lib/python3.10/site-packages/typer/main.py\", line 311, in __call__\n    return get_command(self)(*args, **kwargs)\n", "  File \"/usr/local/lib/python3.10/site-packages/click/core.py\", line 1130, in __call__\n    return self.main(*args, **kwargs)\n", "  File \"/usr/local/lib/python3.10/site-packages/typer/core.py\", line 778, in main\n    return _main(\n", "  File \"/usr/local/lib/python3.10/site-packages/typer/core.py\", line 216, in _main\n    rv = self.invoke(ctx)\n", "  File \"/usr/local/lib/python3.10/site-packages/click/core.py\", line 1657, in invoke\n    return _process_result(sub_ctx.command.invoke(sub_ctx))\n", "  File \"/usr/local/lib/python3.10/site-packages/click/core.py\", line 1404, in invoke\n    return ctx.invoke(self.callback, **ctx.params)\n", "  File \"/usr/local/lib/python3.10/site-packages/click/core.py\", line 760, in invoke\n    return __callback(*args, **kwargs)\n", "  File \"/usr/local/lib/python3.10/site-packages/typer/main.py\", line 683, in wrapper\n    return callback(**use_params)  # type: ignore\n", "  File \"/usr/local/lib/python3.10/site-packages/mage_ai/cli/main.py\", line 147, in start\n    start_server(\n", "  File \"/usr/local/lib/python3.10/site-packages/mage_ai/server/server.py\", line 809, in start_server\n    scheduler_manager.start_scheduler()\n", "  File \"/usr/local/lib/python3.10/site-packages/mage_ai/server/scheduler_manager.py\", line 106, in start_scheduler\n    proc.start()\n", "  File \"/usr/local/lib/python3.10/multiprocessing/process.py\", line 121, in start\n    self._popen = self._Popen(self)\n", "  File \"/usr/local/lib/python3.10/multiprocessing/context.py\", line 224, in _Popen\n    return _default_context.get_context().Process._Popen(process_obj)\n", "  File \"/usr/local/lib/python3.10/multiprocessing/context.py\", line 281, in _Popen\n    return Popen(process_obj)\n", "  File \"/usr/local/lib/python3.10/multiprocessing/popen_fork.py\", line 19, in __init__\n    self._launch(process_obj)\n", "  File \"/usr/local/lib/python3.10/multiprocessing/popen_fork.py\", line 71, in _launch\n    code = process_obj._bootstrap(parent_sentinel=child_r)\n", "  File \"/usr/local/lib/python3.10/multiprocessing/process.py\", line 314, in _bootstrap\n    self.run()\n", "  File \"/usr/local/lib/python3.10/multiprocessing/process.py\", line 108, in run\n    self._target(*self._args, **self._kwargs)\n", "  File \"/usr/local/lib/python3.10/site-packages/mage_ai/orchestration/db/process.py\", line 15, in start_session_and_run\n    results = target(*args)\n", "  File \"/usr/local/lib/python3.10/site-packages/mage_ai/server/scheduler_manager.py\", line 58, in run_scheduler\n    LoopTimeTrigger().start()\n", "  File \"/usr/local/lib/python3.10/site-packages/mage_ai/orchestration/triggers/loop_time_trigger.py\", line 14, in start\n    self.run()\n", "  File \"/usr/local/lib/python3.10/site-packages/mage_ai/orchestration/triggers/time_trigger.py\", line 11, in run\n    schedule_all()\n", "  File \"/usr/local/lib/python3.10/site-packages/mage_ai/orchestration/pipeline_scheduler_original.py\", line 1730, in schedule_all\n    PipelineScheduler(r).schedule()\n", "  File \"/usr/local/lib/python3.10/site-packages/mage_ai/orchestration/db/__init__.py\", line 158, in func_with_rollback\n    return func(*args, **kwargs)\n", "  File \"/usr/local/lib/python3.10/site-packages/mage_ai/orchestration/pipeline_scheduler_original.py\", line 333, in schedule\n    self.__schedule_blocks(block_runs)\n", "  File \"/usr/local/lib/python3.10/site-packages/mage_ai/orchestration/pipeline_scheduler_original.py\", line 640, in __schedule_blocks\n    job_manager.add_job(\n", "  File \"/usr/local/lib/python3.10/site-packages/mage_ai/orchestration/job_manager.py\", line 20, in add_job\n    self.queue.enqueue(job_id, target, *args, **kwargs)\n", "  File \"/usr/local/lib/python3.10/site-packages/mage_ai/orchestration/queue/process_queue.py\", line 121, in enqueue\n    self.start_worker_pool()\n", "  File \"/usr/local/lib/python3.10/site-packages/mage_ai/orchestration/queue/process_queue.py\", line 198, in start_worker_pool\n    self.worker_pool_proc.start()\n", "  File \"/usr/local/lib/python3.10/multiprocessing/process.py\", line 121, in start\n    self._popen = self._Popen(self)\n", "  File \"/usr/local/lib/python3.10/multiprocessing/context.py\", line 224, in _Popen\n    return _default_context.get_context().Process._Popen(process_obj)\n", "  File \"/usr/local/lib/python3.10/multiprocessing/context.py\", line 281, in _Popen\n    return Popen(process_obj)\n", "  File \"/usr/local/lib/python3.10/multiprocessing/popen_fork.py\", line 19, in __init__\n    self._launch(process_obj)\n", "  File \"/usr/local/lib/python3.10/multiprocessing/popen_fork.py\", line 71, in _launch\n    code = process_obj._bootstrap(parent_sentinel=child_r)\n", "  File \"/usr/local/lib/python3.10/multiprocessing/process.py\", line 314, in _bootstrap\n    self.run()\n", "  File \"/usr/local/lib/python3.10/multiprocessing/process.py\", line 108, in run\n    self._target(*self._args, **self._kwargs)\n", "  File \"/usr/local/lib/python3.10/site-packages/mage_ai/orchestration/queue/process_queue.py\", line 351, in poll_job_and_execute\n    worker.start()\n", "  File \"/usr/local/lib/python3.10/multiprocessing/process.py\", line 121, in start\n    self._popen = self._Popen(self)\n", "  File \"/usr/local/lib/python3.10/multiprocessing/context.py\", line 224, in _Popen\n    return _default_context.get_context().Process._Popen(process_obj)\n", "  File \"/usr/local/lib/python3.10/multiprocessing/context.py\", line 281, in _Popen\n    return Popen(process_obj)\n", "  File \"/usr/local/lib/python3.10/multiprocessing/popen_fork.py\", line 19, in __init__\n    self._launch(process_obj)\n", "  File \"/usr/local/lib/python3.10/multiprocessing/popen_fork.py\", line 71, in _launch\n    code = process_obj._bootstrap(parent_sentinel=child_r)\n", "  File \"/usr/local/lib/python3.10/multiprocessing/process.py\", line 314, in _bootstrap\n    self.run()\n", "  File \"/usr/local/lib/python3.10/site-packages/newrelic/api/background_task.py\", line 117, in wrapper\n    return wrapped(*args, **kwargs)\n", "  File \"/usr/local/lib/python3.10/site-packages/mage_ai/orchestration/queue/process_queue.py\", line 315, in run\n    start_session_and_run(args[1], *args[2], **args[3])\n", "  File \"/usr/local/lib/python3.10/site-packages/mage_ai/orchestration/db/process.py\", line 15, in start_session_and_run\n    results = target(*args)\n", "  File \"/usr/local/lib/python3.10/site-packages/mage_ai/orchestration/pipeline_scheduler_original.py\", line 1235, in run_block\n    return ExecutorFactory.get_block_executor(\n", "  File \"/usr/local/lib/python3.10/site-packages/mage_ai/data_preparation/executors/block_executor.py\", line 647, in execute\n    result = __execute_with_retry()\n", "  File \"/usr/local/lib/python3.10/site-packages/mage_ai/shared/retry.py\", line 46, in retry_func\n    logger.warning(\n", "  File \"/usr/local/lib/python3.10/site-packages/mage_ai/data_preparation/logging/logger.py\", line 39, in warning\n    self.__send_message('warning', message, **kwargs)\n", "  File \"/usr/local/lib/python3.10/site-packages/mage_ai/data_preparation/logging/logger.py\", line 65, in __send_message\n    data['error_stack'] = traceback.format_stack()\n"], "error_stacktrace": "Execution failed on sql '\nWITH subquery AS (\n    SELECT * FROM public.real_estate_data_weekly\n)\n\nSELECT *\nFROM subquery\nLIMIT 10000000\n': relation \"public.real_estate_data_weekly\" does not exist\nLINE 3:     SELECT * FROM public.real_estate_data_weekly\n                          ^\n"}
2025-01-21T20:42:44 {"block_run_id": 331, "block_uuid": "data_evaluator", "pipeline_run_id": 36, "pipeline_schedule_id": 30, "pipeline_uuid": "real_estate", "hostname": "72754110c32d", "block_type": "custom", "level": "EXCEPTION", "message": "Failed to execute block data_evaluator", "timestamp": 1737492164.028262, "uuid": "22f04e193fd342eaabf0d0d812b721ec", "error": "Traceback (most recent call last):\n  File \"/usr/local/lib/python3.10/site-packages/pandas/io/sql.py\", line 2018, in execute\n    cur.execute(*args, **kwargs)\npsycopg2.errors.UndefinedTable: relation \"public.real_estate_data_weekly\" does not exist\nLINE 3:     SELECT * FROM public.real_estate_data_weekly\n                          ^\n\n\nThe above exception was the direct cause of the following exception:\n\nTraceback (most recent call last):\n  File \"/usr/local/lib/python3.10/site-packages/mage_ai/data_preparation/executors/block_executor.py\", line 647, in execute\n    result = __execute_with_retry()\n  File \"/usr/local/lib/python3.10/site-packages/mage_ai/shared/retry.py\", line 54, in retry_func\n    raise e\n  File \"/usr/local/lib/python3.10/site-packages/mage_ai/shared/retry.py\", line 38, in retry_func\n    return func(*args, **kwargs)\n  File \"/usr/local/lib/python3.10/site-packages/mage_ai/data_preparation/executors/block_executor.py\", line 621, in __execute_with_retry\n    return self._execute(\n  File \"/usr/local/lib/python3.10/site-packages/mage_ai/data_preparation/executors/block_executor.py\", line 1154, in _execute\n    result = self.block.execute_sync(\n  File \"/usr/local/lib/python3.10/site-packages/mage_ai/data_preparation/models/block/__init__.py\", line 1691, in execute_sync\n    return __execute()\n  File \"/usr/local/lib/python3.10/site-packages/mage_ai/data_preparation/models/block/__init__.py\", line 1668, in __execute\n    raise err\n  File \"/usr/local/lib/python3.10/site-packages/mage_ai/data_preparation/models/block/__init__.py\", line 1570, in __execute\n    output = self.execute_block(\n  File \"/usr/local/lib/python3.10/site-packages/mage_ai/data_preparation/models/block/__init__.py\", line 1910, in execute_block\n    outputs = self._execute_block(\n  File \"/usr/local/lib/python3.10/site-packages/mage_ai/data_preparation/models/block/__init__.py\", line 2073, in _execute_block\n    outputs = self.execute_block_function(\n  File \"/usr/local/lib/python3.10/site-packages/mage_ai/data_preparation/models/block/__init__.py\", line 2169, in execute_block_function\n    output = block_function_updated(*input_vars, **global_vars)\n  File \"<string>\", line 90, in transform_custom\n  File \"/usr/local/lib/python3.10/site-packages/mage_ai/io/sql.py\", line 214, in load\n    return read_sql(\n  File \"/usr/local/lib/python3.10/site-packages/pandas/io/sql.py\", line 564, in read_sql\n    return pandas_sql.read_query(\n  File \"/usr/local/lib/python3.10/site-packages/pandas/io/sql.py\", line 2078, in read_query\n    cursor = self.execute(*args)\n  File \"/usr/local/lib/python3.10/site-packages/pandas/io/sql.py\", line 2030, in execute\n    raise ex from exc\npandas.errors.DatabaseError: Execution failed on sql '\nWITH subquery AS (\n    SELECT * FROM public.real_estate_data_weekly\n)\n\nSELECT *\nFROM subquery\nLIMIT 10000000\n': relation \"public.real_estate_data_weekly\" does not exist\nLINE 3:     SELECT * FROM public.real_estate_data_weekly\n                          ^\n\n", "error_stack": ["  File \"/usr/local/bin/mage\", line 8, in <module>\n    sys.exit(app())\n", "  File \"/usr/local/lib/python3.10/site-packages/typer/main.py\", line 311, in __call__\n    return get_command(self)(*args, **kwargs)\n", "  File \"/usr/local/lib/python3.10/site-packages/click/core.py\", line 1130, in __call__\n    return self.main(*args, **kwargs)\n", "  File \"/usr/local/lib/python3.10/site-packages/typer/core.py\", line 778, in main\n    return _main(\n", "  File \"/usr/local/lib/python3.10/site-packages/typer/core.py\", line 216, in _main\n    rv = self.invoke(ctx)\n", "  File \"/usr/local/lib/python3.10/site-packages/click/core.py\", line 1657, in invoke\n    return _process_result(sub_ctx.command.invoke(sub_ctx))\n", "  File \"/usr/local/lib/python3.10/site-packages/click/core.py\", line 1404, in invoke\n    return ctx.invoke(self.callback, **ctx.params)\n", "  File \"/usr/local/lib/python3.10/site-packages/click/core.py\", line 760, in invoke\n    return __callback(*args, **kwargs)\n", "  File \"/usr/local/lib/python3.10/site-packages/typer/main.py\", line 683, in wrapper\n    return callback(**use_params)  # type: ignore\n", "  File \"/usr/local/lib/python3.10/site-packages/mage_ai/cli/main.py\", line 147, in start\n    start_server(\n", "  File \"/usr/local/lib/python3.10/site-packages/mage_ai/server/server.py\", line 809, in start_server\n    scheduler_manager.start_scheduler()\n", "  File \"/usr/local/lib/python3.10/site-packages/mage_ai/server/scheduler_manager.py\", line 106, in start_scheduler\n    proc.start()\n", "  File \"/usr/local/lib/python3.10/multiprocessing/process.py\", line 121, in start\n    self._popen = self._Popen(self)\n", "  File \"/usr/local/lib/python3.10/multiprocessing/context.py\", line 224, in _Popen\n    return _default_context.get_context().Process._Popen(process_obj)\n", "  File \"/usr/local/lib/python3.10/multiprocessing/context.py\", line 281, in _Popen\n    return Popen(process_obj)\n", "  File \"/usr/local/lib/python3.10/multiprocessing/popen_fork.py\", line 19, in __init__\n    self._launch(process_obj)\n", "  File \"/usr/local/lib/python3.10/multiprocessing/popen_fork.py\", line 71, in _launch\n    code = process_obj._bootstrap(parent_sentinel=child_r)\n", "  File \"/usr/local/lib/python3.10/multiprocessing/process.py\", line 314, in _bootstrap\n    self.run()\n", "  File \"/usr/local/lib/python3.10/multiprocessing/process.py\", line 108, in run\n    self._target(*self._args, **self._kwargs)\n", "  File \"/usr/local/lib/python3.10/site-packages/mage_ai/orchestration/db/process.py\", line 15, in start_session_and_run\n    results = target(*args)\n", "  File \"/usr/local/lib/python3.10/site-packages/mage_ai/server/scheduler_manager.py\", line 58, in run_scheduler\n    LoopTimeTrigger().start()\n", "  File \"/usr/local/lib/python3.10/site-packages/mage_ai/orchestration/triggers/loop_time_trigger.py\", line 14, in start\n    self.run()\n", "  File \"/usr/local/lib/python3.10/site-packages/mage_ai/orchestration/triggers/time_trigger.py\", line 11, in run\n    schedule_all()\n", "  File \"/usr/local/lib/python3.10/site-packages/mage_ai/orchestration/pipeline_scheduler_original.py\", line 1730, in schedule_all\n    PipelineScheduler(r).schedule()\n", "  File \"/usr/local/lib/python3.10/site-packages/mage_ai/orchestration/db/__init__.py\", line 158, in func_with_rollback\n    return func(*args, **kwargs)\n", "  File \"/usr/local/lib/python3.10/site-packages/mage_ai/orchestration/pipeline_scheduler_original.py\", line 333, in schedule\n    self.__schedule_blocks(block_runs)\n", "  File \"/usr/local/lib/python3.10/site-packages/mage_ai/orchestration/pipeline_scheduler_original.py\", line 640, in __schedule_blocks\n    job_manager.add_job(\n", "  File \"/usr/local/lib/python3.10/site-packages/mage_ai/orchestration/job_manager.py\", line 20, in add_job\n    self.queue.enqueue(job_id, target, *args, **kwargs)\n", "  File \"/usr/local/lib/python3.10/site-packages/mage_ai/orchestration/queue/process_queue.py\", line 121, in enqueue\n    self.start_worker_pool()\n", "  File \"/usr/local/lib/python3.10/site-packages/mage_ai/orchestration/queue/process_queue.py\", line 198, in start_worker_pool\n    self.worker_pool_proc.start()\n", "  File \"/usr/local/lib/python3.10/multiprocessing/process.py\", line 121, in start\n    self._popen = self._Popen(self)\n", "  File \"/usr/local/lib/python3.10/multiprocessing/context.py\", line 224, in _Popen\n    return _default_context.get_context().Process._Popen(process_obj)\n", "  File \"/usr/local/lib/python3.10/multiprocessing/context.py\", line 281, in _Popen\n    return Popen(process_obj)\n", "  File \"/usr/local/lib/python3.10/multiprocessing/popen_fork.py\", line 19, in __init__\n    self._launch(process_obj)\n", "  File \"/usr/local/lib/python3.10/multiprocessing/popen_fork.py\", line 71, in _launch\n    code = process_obj._bootstrap(parent_sentinel=child_r)\n", "  File \"/usr/local/lib/python3.10/multiprocessing/process.py\", line 314, in _bootstrap\n    self.run()\n", "  File \"/usr/local/lib/python3.10/multiprocessing/process.py\", line 108, in run\n    self._target(*self._args, **self._kwargs)\n", "  File \"/usr/local/lib/python3.10/site-packages/mage_ai/orchestration/queue/process_queue.py\", line 351, in poll_job_and_execute\n    worker.start()\n", "  File \"/usr/local/lib/python3.10/multiprocessing/process.py\", line 121, in start\n    self._popen = self._Popen(self)\n", "  File \"/usr/local/lib/python3.10/multiprocessing/context.py\", line 224, in _Popen\n    return _default_context.get_context().Process._Popen(process_obj)\n", "  File \"/usr/local/lib/python3.10/multiprocessing/context.py\", line 281, in _Popen\n    return Popen(process_obj)\n", "  File \"/usr/local/lib/python3.10/multiprocessing/popen_fork.py\", line 19, in __init__\n    self._launch(process_obj)\n", "  File \"/usr/local/lib/python3.10/multiprocessing/popen_fork.py\", line 71, in _launch\n    code = process_obj._bootstrap(parent_sentinel=child_r)\n", "  File \"/usr/local/lib/python3.10/multiprocessing/process.py\", line 314, in _bootstrap\n    self.run()\n", "  File \"/usr/local/lib/python3.10/site-packages/newrelic/api/background_task.py\", line 117, in wrapper\n    return wrapped(*args, **kwargs)\n", "  File \"/usr/local/lib/python3.10/site-packages/mage_ai/orchestration/queue/process_queue.py\", line 315, in run\n    start_session_and_run(args[1], *args[2], **args[3])\n", "  File \"/usr/local/lib/python3.10/site-packages/mage_ai/orchestration/db/process.py\", line 15, in start_session_and_run\n    results = target(*args)\n", "  File \"/usr/local/lib/python3.10/site-packages/mage_ai/orchestration/pipeline_scheduler_original.py\", line 1235, in run_block\n    return ExecutorFactory.get_block_executor(\n", "  File \"/usr/local/lib/python3.10/site-packages/mage_ai/data_preparation/executors/block_executor.py\", line 649, in execute\n    self.logger.exception(\n", "  File \"/usr/local/lib/python3.10/site-packages/mage_ai/data_preparation/logging/logger.py\", line 30, in exception\n    self.__send_message('exception', message, **kwargs)\n", "  File \"/usr/local/lib/python3.10/site-packages/mage_ai/data_preparation/logging/logger.py\", line 65, in __send_message\n    data['error_stack'] = traceback.format_stack()\n"], "error_stacktrace": "Execution failed on sql '\nWITH subquery AS (\n    SELECT * FROM public.real_estate_data_weekly\n)\n\nSELECT *\nFROM subquery\nLIMIT 10000000\n': relation \"public.real_estate_data_weekly\" does not exist\nLINE 3:     SELECT * FROM public.real_estate_data_weekly\n                          ^\n"}
Traceback (most recent call last):
  File "/usr/local/lib/python3.10/site-packages/pandas/io/sql.py", line 2018, in execute
    cur.execute(*args, **kwargs)
psycopg2.errors.UndefinedTable: relation "public.real_estate_data_weekly" does not exist
LINE 3:     SELECT * FROM public.real_estate_data_weekly
                          ^


The above exception was the direct cause of the following exception:

Traceback (most recent call last):
  File "/usr/local/lib/python3.10/site-packages/mage_ai/data_preparation/executors/block_executor.py", line 647, in execute
    result = __execute_with_retry()
  File "/usr/local/lib/python3.10/site-packages/mage_ai/shared/retry.py", line 54, in retry_func
    raise e
  File "/usr/local/lib/python3.10/site-packages/mage_ai/shared/retry.py", line 38, in retry_func
    return func(*args, **kwargs)
  File "/usr/local/lib/python3.10/site-packages/mage_ai/data_preparation/executors/block_executor.py", line 621, in __execute_with_retry
    return self._execute(
  File "/usr/local/lib/python3.10/site-packages/mage_ai/data_preparation/executors/block_executor.py", line 1154, in _execute
    result = self.block.execute_sync(
  File "/usr/local/lib/python3.10/site-packages/mage_ai/data_preparation/models/block/__init__.py", line 1691, in execute_sync
    return __execute()
  File "/usr/local/lib/python3.10/site-packages/mage_ai/data_preparation/models/block/__init__.py", line 1668, in __execute
    raise err
  File "/usr/local/lib/python3.10/site-packages/mage_ai/data_preparation/models/block/__init__.py", line 1570, in __execute
    output = self.execute_block(
  File "/usr/local/lib/python3.10/site-packages/mage_ai/data_preparation/models/block/__init__.py", line 1910, in execute_block
    outputs = self._execute_block(
  File "/usr/local/lib/python3.10/site-packages/mage_ai/data_preparation/models/block/__init__.py", line 2073, in _execute_block
    outputs = self.execute_block_function(
  File "/usr/local/lib/python3.10/site-packages/mage_ai/data_preparation/models/block/__init__.py", line 2169, in execute_block_function
    output = block_function_updated(*input_vars, **global_vars)
  File "<string>", line 90, in transform_custom
  File "/usr/local/lib/python3.10/site-packages/mage_ai/io/sql.py", line 214, in load
    return read_sql(
  File "/usr/local/lib/python3.10/site-packages/pandas/io/sql.py", line 564, in read_sql
    return pandas_sql.read_query(
  File "/usr/local/lib/python3.10/site-packages/pandas/io/sql.py", line 2078, in read_query
    cursor = self.execute(*args)
  File "/usr/local/lib/python3.10/site-packages/pandas/io/sql.py", line 2030, in execute
    raise ex from exc
pandas.errors.DatabaseError: Execution failed on sql '
WITH subquery AS (
    SELECT * FROM public.real_estate_data_weekly
)

SELECT *
FROM subquery
LIMIT 10000000
': relation "public.real_estate_data_weekly" does not exist
LINE 3:     SELECT * FROM public.real_estate_data_weekly
                          ^

