2025-01-21T20:39:43 {"cpu": 0.45458984375, "cpu_total": 2, "cpu_usage": 0.227294921875, "memory": 2456.0, "memory_total": 3924.0, "memory_usage": 0.6258919469928644, "pipeline_run_id": 35, "pipeline_schedule_id": 29, "pipeline_uuid": "real_estate", "hostname": "72754110c32d", "level": "INFO", "message": "Pipeline real_estate for run 35 in schedule 29 is alive.", "timestamp": 1737491983.77696, "uuid": "a79db1db005d4d2fb8dddeaf31d2f38b"}
2025-01-21T20:39:43 {"cpu": 0.45458984375, "cpu_total": 2, "cpu_usage": 0.227294921875, "memory": 2487.0, "memory_total": 3924.0, "memory_usage": 0.6337920489296636, "pipeline_run_id": 35, "pipeline_schedule_id": 29, "pipeline_uuid": "real_estate", "hostname": "72754110c32d", "level": "INFO", "message": "Pipeline real_estate for run 35 in schedule 29 is alive.", "timestamp": 1737491983.886307, "uuid": "a4318385a4dc43178d08ad23b841d3e5"}
2025-01-21T20:39:44 {"block_run_id": 312, "block_uuid": "kaggle_loader", "pipeline_run_id": 35, "pipeline_schedule_id": 29, "pipeline_uuid": "real_estate", "hostname": "72754110c32d", "level": "INFO", "message": "Execute PipelineRun 35, BlockRun 312: pipeline real_estate block kaggle_loader", "timestamp": 1737491984.008492, "uuid": "e2223eed14d7490789c9be40b1e3e8de"}
2025-01-21T20:39:44 {"block_run_id": 317, "block_uuid": "loads_real_estate_table", "pipeline_run_id": 35, "pipeline_schedule_id": 29, "pipeline_uuid": "real_estate", "hostname": "72754110c32d", "level": "INFO", "message": "Execute PipelineRun 35, BlockRun 317: pipeline real_estate block loads_real_estate_table", "timestamp": 1737491984.010064, "uuid": "d7211984c4764fe88a5e2b430424ba88"}
2025-01-21T20:39:48 {"block_run_id": 312, "block_uuid": "kaggle_loader", "pipeline_run_id": 35, "pipeline_schedule_id": 29, "pipeline_uuid": "real_estate", "hostname": "72754110c32d", "level": "INFO", "message": "BlockRun 312 (block_uuid: kaggle_loader) completes.", "timestamp": 1737491988.739602, "uuid": "7a2b664767a64dedb13146b1ef05de80"}
2025-01-21T20:39:48 {"block_run_id": 317, "block_uuid": "loads_real_estate_table", "pipeline_run_id": 35, "pipeline_schedule_id": 29, "pipeline_uuid": "real_estate", "hostname": "72754110c32d", "level": "INFO", "message": "BlockRun 317 (block_uuid: loads_real_estate_table) completes.", "timestamp": 1737491988.833291, "uuid": "0aa078cf4a89403fb21278a39aeb688c"}
2025-01-21T20:39:54 {"cpu": 0.46533203125, "cpu_total": 2, "cpu_usage": 0.232666015625, "memory": 2455.0, "memory_total": 3924.0, "memory_usage": 0.6256371049949032, "pipeline_run_id": 35, "pipeline_schedule_id": 29, "pipeline_uuid": "real_estate", "hostname": "72754110c32d", "level": "INFO", "message": "Pipeline real_estate for run 35 in schedule 29 is alive.", "timestamp": 1737491994.413178, "uuid": "7f49a3763ff348569a38e8677847c85c"}
2025-01-21T20:39:54 {"block_run_id": 313, "block_uuid": "cleans_dataframe", "pipeline_run_id": 35, "pipeline_schedule_id": 29, "pipeline_uuid": "real_estate", "hostname": "72754110c32d", "level": "INFO", "message": "Execute PipelineRun 35, BlockRun 313: pipeline real_estate block cleans_dataframe", "timestamp": 1737491994.585561, "uuid": "708ed4281af0400d803f058acd71debf"}
2025-01-21T20:39:54 {"block_run_id": 320, "block_uuid": "data_evaluator", "pipeline_run_id": 35, "pipeline_schedule_id": 29, "pipeline_uuid": "real_estate", "hostname": "72754110c32d", "level": "INFO", "message": "Execute PipelineRun 35, BlockRun 320: pipeline real_estate block data_evaluator", "timestamp": 1737491994.599206, "uuid": "94649b6aedfd4668b994a477349683af"}
2025-01-21T20:40:03 {"cpu": 0.47119140625, "cpu_total": 2, "cpu_usage": 0.235595703125, "memory": 2975.0, "memory_total": 3924.0, "memory_usage": 0.7581549439347605, "pipeline_run_id": 35, "pipeline_schedule_id": 29, "pipeline_uuid": "real_estate", "hostname": "72754110c32d", "level": "INFO", "message": "Pipeline real_estate for run 35 in schedule 29 is alive.", "timestamp": 1737492003.569656, "uuid": "028be0a4aa784730ab54767fae730f87"}
2025-01-21T20:40:04 {"block_run_id": 313, "block_uuid": "cleans_dataframe", "pipeline_run_id": 35, "pipeline_schedule_id": 29, "pipeline_uuid": "real_estate", "hostname": "72754110c32d", "level": "INFO", "message": "BlockRun 313 (block_uuid: cleans_dataframe) completes.", "timestamp": 1737492004.657448, "uuid": "3f40145abe5e4959b00c0a383a6bbda7"}
2025-01-21T20:40:05 {"block_run_id": 320, "block_uuid": "data_evaluator", "pipeline_run_id": 35, "pipeline_schedule_id": 29, "pipeline_uuid": "real_estate", "hostname": "72754110c32d", "level": "EXCEPTION", "message": "BlockRun 320 (block_uuid: data_evaluator) failed.", "timestamp": 1737492005.407298, "uuid": "9c2a20c09557460aac4044db09f4c938", "error": "Traceback (most recent call last):\n  File \"/usr/local/lib/python3.10/site-packages/pandas/io/sql.py\", line 2018, in execute\n    cur.execute(*args, **kwargs)\npsycopg2.errors.UndefinedTable: relation \"public.real_estate_data_weekly\" does not exist\nLINE 3:     SELECT * FROM public.real_estate_data_weekly\n                          ^\n\n\nThe above exception was the direct cause of the following exception:\n\nTraceback (most recent call last):\n  File \"/usr/local/lib/python3.10/site-packages/mage_ai/data_preparation/executors/block_executor.py\", line 647, in execute\n    result = __execute_with_retry()\n  File \"/usr/local/lib/python3.10/site-packages/mage_ai/shared/retry.py\", line 54, in retry_func\n    raise e\n  File \"/usr/local/lib/python3.10/site-packages/mage_ai/shared/retry.py\", line 38, in retry_func\n    return func(*args, **kwargs)\n  File \"/usr/local/lib/python3.10/site-packages/mage_ai/data_preparation/executors/block_executor.py\", line 621, in __execute_with_retry\n    return self._execute(\n  File \"/usr/local/lib/python3.10/site-packages/mage_ai/data_preparation/executors/block_executor.py\", line 1154, in _execute\n    result = self.block.execute_sync(\n  File \"/usr/local/lib/python3.10/site-packages/mage_ai/data_preparation/models/block/__init__.py\", line 1691, in execute_sync\n    return __execute()\n  File \"/usr/local/lib/python3.10/site-packages/mage_ai/data_preparation/models/block/__init__.py\", line 1668, in __execute\n    raise err\n  File \"/usr/local/lib/python3.10/site-packages/mage_ai/data_preparation/models/block/__init__.py\", line 1570, in __execute\n    output = self.execute_block(\n  File \"/usr/local/lib/python3.10/site-packages/mage_ai/data_preparation/models/block/__init__.py\", line 1910, in execute_block\n    outputs = self._execute_block(\n  File \"/usr/local/lib/python3.10/site-packages/mage_ai/data_preparation/models/block/__init__.py\", line 2073, in _execute_block\n    outputs = self.execute_block_function(\n  File \"/usr/local/lib/python3.10/site-packages/mage_ai/data_preparation/models/block/__init__.py\", line 2169, in execute_block_function\n    output = block_function_updated(*input_vars, **global_vars)\n  File \"<string>\", line 90, in transform_custom\n  File \"/usr/local/lib/python3.10/site-packages/mage_ai/io/sql.py\", line 214, in load\n    return read_sql(\n  File \"/usr/local/lib/python3.10/site-packages/pandas/io/sql.py\", line 564, in read_sql\n    return pandas_sql.read_query(\n  File \"/usr/local/lib/python3.10/site-packages/pandas/io/sql.py\", line 2078, in read_query\n    cursor = self.execute(*args)\n  File \"/usr/local/lib/python3.10/site-packages/pandas/io/sql.py\", line 2030, in execute\n    raise ex from exc\npandas.errors.DatabaseError: Execution failed on sql '\nWITH subquery AS (\n    SELECT * FROM public.real_estate_data_weekly\n)\n\nSELECT *\nFROM subquery\nLIMIT 10000000\n': relation \"public.real_estate_data_weekly\" does not exist\nLINE 3:     SELECT * FROM public.real_estate_data_weekly\n                          ^\n\n", "error_stack": ["  File \"/usr/local/bin/mage\", line 8, in <module>\n    sys.exit(app())\n", "  File \"/usr/local/lib/python3.10/site-packages/typer/main.py\", line 311, in __call__\n    return get_command(self)(*args, **kwargs)\n", "  File \"/usr/local/lib/python3.10/site-packages/click/core.py\", line 1130, in __call__\n    return self.main(*args, **kwargs)\n", "  File \"/usr/local/lib/python3.10/site-packages/typer/core.py\", line 778, in main\n    return _main(\n", "  File \"/usr/local/lib/python3.10/site-packages/typer/core.py\", line 216, in _main\n    rv = self.invoke(ctx)\n", "  File \"/usr/local/lib/python3.10/site-packages/click/core.py\", line 1657, in invoke\n    return _process_result(sub_ctx.command.invoke(sub_ctx))\n", "  File \"/usr/local/lib/python3.10/site-packages/click/core.py\", line 1404, in invoke\n    return ctx.invoke(self.callback, **ctx.params)\n", "  File \"/usr/local/lib/python3.10/site-packages/click/core.py\", line 760, in invoke\n    return __callback(*args, **kwargs)\n", "  File \"/usr/local/lib/python3.10/site-packages/typer/main.py\", line 683, in wrapper\n    return callback(**use_params)  # type: ignore\n", "  File \"/usr/local/lib/python3.10/site-packages/mage_ai/cli/main.py\", line 147, in start\n    start_server(\n", "  File \"/usr/local/lib/python3.10/site-packages/mage_ai/server/server.py\", line 809, in start_server\n    scheduler_manager.start_scheduler()\n", "  File \"/usr/local/lib/python3.10/site-packages/mage_ai/server/scheduler_manager.py\", line 106, in start_scheduler\n    proc.start()\n", "  File \"/usr/local/lib/python3.10/multiprocessing/process.py\", line 121, in start\n    self._popen = self._Popen(self)\n", "  File \"/usr/local/lib/python3.10/multiprocessing/context.py\", line 224, in _Popen\n    return _default_context.get_context().Process._Popen(process_obj)\n", "  File \"/usr/local/lib/python3.10/multiprocessing/context.py\", line 281, in _Popen\n    return Popen(process_obj)\n", "  File \"/usr/local/lib/python3.10/multiprocessing/popen_fork.py\", line 19, in __init__\n    self._launch(process_obj)\n", "  File \"/usr/local/lib/python3.10/multiprocessing/popen_fork.py\", line 71, in _launch\n    code = process_obj._bootstrap(parent_sentinel=child_r)\n", "  File \"/usr/local/lib/python3.10/multiprocessing/process.py\", line 314, in _bootstrap\n    self.run()\n", "  File \"/usr/local/lib/python3.10/multiprocessing/process.py\", line 108, in run\n    self._target(*self._args, **self._kwargs)\n", "  File \"/usr/local/lib/python3.10/site-packages/mage_ai/orchestration/db/process.py\", line 15, in start_session_and_run\n    results = target(*args)\n", "  File \"/usr/local/lib/python3.10/site-packages/mage_ai/server/scheduler_manager.py\", line 58, in run_scheduler\n    LoopTimeTrigger().start()\n", "  File \"/usr/local/lib/python3.10/site-packages/mage_ai/orchestration/triggers/loop_time_trigger.py\", line 14, in start\n    self.run()\n", "  File \"/usr/local/lib/python3.10/site-packages/mage_ai/orchestration/triggers/time_trigger.py\", line 11, in run\n    schedule_all()\n", "  File \"/usr/local/lib/python3.10/site-packages/mage_ai/orchestration/pipeline_scheduler_original.py\", line 1730, in schedule_all\n    PipelineScheduler(r).schedule()\n", "  File \"/usr/local/lib/python3.10/site-packages/mage_ai/orchestration/db/__init__.py\", line 158, in func_with_rollback\n    return func(*args, **kwargs)\n", "  File \"/usr/local/lib/python3.10/site-packages/mage_ai/orchestration/pipeline_scheduler_original.py\", line 333, in schedule\n    self.__schedule_blocks(block_runs)\n", "  File \"/usr/local/lib/python3.10/site-packages/mage_ai/orchestration/pipeline_scheduler_original.py\", line 640, in __schedule_blocks\n    job_manager.add_job(\n", "  File \"/usr/local/lib/python3.10/site-packages/mage_ai/orchestration/job_manager.py\", line 20, in add_job\n    self.queue.enqueue(job_id, target, *args, **kwargs)\n", "  File \"/usr/local/lib/python3.10/site-packages/mage_ai/orchestration/queue/process_queue.py\", line 121, in enqueue\n    self.start_worker_pool()\n", "  File \"/usr/local/lib/python3.10/site-packages/mage_ai/orchestration/queue/process_queue.py\", line 198, in start_worker_pool\n    self.worker_pool_proc.start()\n", "  File \"/usr/local/lib/python3.10/multiprocessing/process.py\", line 121, in start\n    self._popen = self._Popen(self)\n", "  File \"/usr/local/lib/python3.10/multiprocessing/context.py\", line 224, in _Popen\n    return _default_context.get_context().Process._Popen(process_obj)\n", "  File \"/usr/local/lib/python3.10/multiprocessing/context.py\", line 281, in _Popen\n    return Popen(process_obj)\n", "  File \"/usr/local/lib/python3.10/multiprocessing/popen_fork.py\", line 19, in __init__\n    self._launch(process_obj)\n", "  File \"/usr/local/lib/python3.10/multiprocessing/popen_fork.py\", line 71, in _launch\n    code = process_obj._bootstrap(parent_sentinel=child_r)\n", "  File \"/usr/local/lib/python3.10/multiprocessing/process.py\", line 314, in _bootstrap\n    self.run()\n", "  File \"/usr/local/lib/python3.10/multiprocessing/process.py\", line 108, in run\n    self._target(*self._args, **self._kwargs)\n", "  File \"/usr/local/lib/python3.10/site-packages/mage_ai/orchestration/queue/process_queue.py\", line 351, in poll_job_and_execute\n    worker.start()\n", "  File \"/usr/local/lib/python3.10/multiprocessing/process.py\", line 121, in start\n    self._popen = self._Popen(self)\n", "  File \"/usr/local/lib/python3.10/multiprocessing/context.py\", line 224, in _Popen\n    return _default_context.get_context().Process._Popen(process_obj)\n", "  File \"/usr/local/lib/python3.10/multiprocessing/context.py\", line 281, in _Popen\n    return Popen(process_obj)\n", "  File \"/usr/local/lib/python3.10/multiprocessing/popen_fork.py\", line 19, in __init__\n    self._launch(process_obj)\n", "  File \"/usr/local/lib/python3.10/multiprocessing/popen_fork.py\", line 71, in _launch\n    code = process_obj._bootstrap(parent_sentinel=child_r)\n", "  File \"/usr/local/lib/python3.10/multiprocessing/process.py\", line 314, in _bootstrap\n    self.run()\n", "  File \"/usr/local/lib/python3.10/site-packages/newrelic/api/background_task.py\", line 117, in wrapper\n    return wrapped(*args, **kwargs)\n", "  File \"/usr/local/lib/python3.10/site-packages/mage_ai/orchestration/queue/process_queue.py\", line 315, in run\n    start_session_and_run(args[1], *args[2], **args[3])\n", "  File \"/usr/local/lib/python3.10/site-packages/mage_ai/orchestration/db/process.py\", line 15, in start_session_and_run\n    results = target(*args)\n", "  File \"/usr/local/lib/python3.10/site-packages/mage_ai/orchestration/pipeline_scheduler_original.py\", line 1235, in run_block\n    return ExecutorFactory.get_block_executor(\n", "  File \"/usr/local/lib/python3.10/site-packages/mage_ai/data_preparation/executors/block_executor.py\", line 682, in execute\n    on_failure(\n", "  File \"/usr/local/lib/python3.10/site-packages/mage_ai/orchestration/db/__init__.py\", line 158, in func_with_rollback\n    return func(*args, **kwargs)\n", "  File \"/usr/local/lib/python3.10/site-packages/mage_ai/orchestration/pipeline_scheduler_original.py\", line 464, in on_block_failure\n    self.logger.exception(\n", "  File \"/usr/local/lib/python3.10/site-packages/mage_ai/data_preparation/logging/logger.py\", line 30, in exception\n    self.__send_message('exception', message, **kwargs)\n", "  File \"/usr/local/lib/python3.10/site-packages/mage_ai/data_preparation/logging/logger.py\", line 65, in __send_message\n    data['error_stack'] = traceback.format_stack()\n"], "error_stacktrace": "Execution failed on sql '\nWITH subquery AS (\n    SELECT * FROM public.real_estate_data_weekly\n)\n\nSELECT *\nFROM subquery\nLIMIT 10000000\n': relation \"public.real_estate_data_weekly\" does not exist\nLINE 3:     SELECT * FROM public.real_estate_data_weekly\n                          ^\n"}
Traceback (most recent call last):
  File "/usr/local/lib/python3.10/site-packages/pandas/io/sql.py", line 2018, in execute
    cur.execute(*args, **kwargs)
psycopg2.errors.UndefinedTable: relation "public.real_estate_data_weekly" does not exist
LINE 3:     SELECT * FROM public.real_estate_data_weekly
                          ^


The above exception was the direct cause of the following exception:

Traceback (most recent call last):
  File "/usr/local/lib/python3.10/site-packages/mage_ai/data_preparation/executors/block_executor.py", line 647, in execute
    result = __execute_with_retry()
  File "/usr/local/lib/python3.10/site-packages/mage_ai/shared/retry.py", line 54, in retry_func
    raise e
  File "/usr/local/lib/python3.10/site-packages/mage_ai/shared/retry.py", line 38, in retry_func
    return func(*args, **kwargs)
  File "/usr/local/lib/python3.10/site-packages/mage_ai/data_preparation/executors/block_executor.py", line 621, in __execute_with_retry
    return self._execute(
  File "/usr/local/lib/python3.10/site-packages/mage_ai/data_preparation/executors/block_executor.py", line 1154, in _execute
    result = self.block.execute_sync(
  File "/usr/local/lib/python3.10/site-packages/mage_ai/data_preparation/models/block/__init__.py", line 1691, in execute_sync
    return __execute()
  File "/usr/local/lib/python3.10/site-packages/mage_ai/data_preparation/models/block/__init__.py", line 1668, in __execute
    raise err
  File "/usr/local/lib/python3.10/site-packages/mage_ai/data_preparation/models/block/__init__.py", line 1570, in __execute
    output = self.execute_block(
  File "/usr/local/lib/python3.10/site-packages/mage_ai/data_preparation/models/block/__init__.py", line 1910, in execute_block
    outputs = self._execute_block(
  File "/usr/local/lib/python3.10/site-packages/mage_ai/data_preparation/models/block/__init__.py", line 2073, in _execute_block
    outputs = self.execute_block_function(
  File "/usr/local/lib/python3.10/site-packages/mage_ai/data_preparation/models/block/__init__.py", line 2169, in execute_block_function
    output = block_function_updated(*input_vars, **global_vars)
  File "<string>", line 90, in transform_custom
  File "/usr/local/lib/python3.10/site-packages/mage_ai/io/sql.py", line 214, in load
    return read_sql(
  File "/usr/local/lib/python3.10/site-packages/pandas/io/sql.py", line 564, in read_sql
    return pandas_sql.read_query(
  File "/usr/local/lib/python3.10/site-packages/pandas/io/sql.py", line 2078, in read_query
    cursor = self.execute(*args)
  File "/usr/local/lib/python3.10/site-packages/pandas/io/sql.py", line 2030, in execute
    raise ex from exc
pandas.errors.DatabaseError: Execution failed on sql '
WITH subquery AS (
    SELECT * FROM public.real_estate_data_weekly
)

SELECT *
FROM subquery
LIMIT 10000000
': relation "public.real_estate_data_weekly" does not exist
LINE 3:     SELECT * FROM public.real_estate_data_weekly
                          ^

2025-01-21T20:40:13 {"cpu": 0.4765625, "cpu_total": 2, "cpu_usage": 0.23828125, "memory": 2451.0, "memory_total": 3924.0, "memory_usage": 0.6246177370030581, "pipeline_run_id": 35, "pipeline_schedule_id": 29, "pipeline_uuid": "real_estate", "hostname": "72754110c32d", "level": "INFO", "message": "Pipeline real_estate for run 35 in schedule 29 is alive.", "timestamp": 1737492013.664209, "uuid": "6567d1c1ea7b4e94833f8aab04132fc8"}
