2025-01-16T20:53:00 {"block_run_id": 73, "block_uuid": "loads_real_estate_table", "pipeline_run_id": 11, "pipeline_schedule_id": 11, "pipeline_uuid": "real_estate", "hostname": "85d76567f04f", "block_type": "data_loader", "level": "INFO", "message": "Start executing block with BlockExecutor.", "timestamp": 1737060780.090841, "uuid": "f8c575479e4c4ea5aa87e6d620b3a325"}
2025-01-16T20:53:00 {"block_run_id": 73, "block_uuid": "loads_real_estate_table", "pipeline_run_id": 11, "pipeline_schedule_id": 11, "pipeline_uuid": "real_estate", "hostname": "85d76567f04f", "block_type": "data_loader", "level": "INFO", "message": "Postgres initialized", "timestamp": 1737060780.200487, "uuid": "0f37bf70a9544b62bd019324d4125e00"}
2025-01-16T20:53:00 {"block_run_id": 73, "block_uuid": "loads_real_estate_table", "pipeline_run_id": 11, "pipeline_schedule_id": 11, "pipeline_uuid": "real_estate", "hostname": "85d76567f04f", "block_type": "data_loader", "level": "INFO", "message": "\u2514\u2500 Opening connection to PostgreSQL database...", "timestamp": 1737060780.200987, "uuid": "063fc074084a4c32b9b1191fce373470"}
2025-01-16T20:53:00 {"block_run_id": 73, "block_uuid": "loads_real_estate_table", "pipeline_run_id": 11, "pipeline_schedule_id": 11, "pipeline_uuid": "real_estate", "hostname": "85d76567f04f", "block_type": "data_loader", "level": "INFO", "message": "Traceback (most recent call last):", "timestamp": 1737060780.216271, "uuid": "8b518a7a5a7144e19221e2336509cc8e"}
2025-01-16T20:53:00 {"block_run_id": 73, "block_uuid": "loads_real_estate_table", "pipeline_run_id": 11, "pipeline_schedule_id": 11, "pipeline_uuid": "real_estate", "hostname": "85d76567f04f", "block_type": "data_loader", "level": "INFO", "message": "  File \"/usr/local/lib/python3.10/site-packages/mage_ai/io/postgres.py\", line 163, in open", "timestamp": 1737060780.216684, "uuid": "f57a8ae9e3ee4388977b3027292b1fae"}
2025-01-16T20:53:00 {"block_run_id": 73, "block_uuid": "loads_real_estate_table", "pipeline_run_id": 11, "pipeline_schedule_id": 11, "pipeline_uuid": "real_estate", "hostname": "85d76567f04f", "block_type": "data_loader", "level": "INFO", "message": "    self._ctx = connect(**connect_opts)", "timestamp": 1737060780.217458, "uuid": "b2832987b2964f19aea6008f51a6a403"}
2025-01-16T20:53:00 {"block_run_id": 73, "block_uuid": "loads_real_estate_table", "pipeline_run_id": 11, "pipeline_schedule_id": 11, "pipeline_uuid": "real_estate", "hostname": "85d76567f04f", "block_type": "data_loader", "level": "INFO", "message": "  File \"/usr/local/lib/python3.10/site-packages/psycopg2/__init__.py\", line 122, in connect", "timestamp": 1737060780.217798, "uuid": "1dfba32b2a3c46999e53230bf04b559d"}
2025-01-16T20:53:00 {"block_run_id": 73, "block_uuid": "loads_real_estate_table", "pipeline_run_id": 11, "pipeline_schedule_id": 11, "pipeline_uuid": "real_estate", "hostname": "85d76567f04f", "block_type": "data_loader", "level": "INFO", "message": "    conn = _connect(dsn, connection_factory=connection_factory, **kwasync)", "timestamp": 1737060780.218069, "uuid": "5ed5f441682b4160a43c2f3a1c296aef"}
2025-01-16T20:53:00 {"block_run_id": 73, "block_uuid": "loads_real_estate_table", "pipeline_run_id": 11, "pipeline_schedule_id": 11, "pipeline_uuid": "real_estate", "hostname": "85d76567f04f", "block_type": "data_loader", "level": "INFO", "message": "psycopg2.OperationalError: connection to server at \"postgres\" (172.18.0.2), port 5432 failed: FATAL:  database \"mage_db\" does not exist", "timestamp": 1737060780.218357, "uuid": "82c056c9d18b4a139f24e7af6ff10a30"}
2025-01-16T20:53:00 {"block_run_id": 73, "block_uuid": "loads_real_estate_table", "pipeline_run_id": 11, "pipeline_schedule_id": 11, "pipeline_uuid": "real_estate", "hostname": "85d76567f04f", "block_type": "data_loader", "level": "INFO", "message": "DONE", "timestamp": 1737060780.218641, "uuid": "a31e5f415e984cb68be747171f1bfd70"}
2025-01-16T20:53:00 {"block_run_id": 73, "block_uuid": "loads_real_estate_table", "pipeline_run_id": 11, "pipeline_schedule_id": 11, "pipeline_uuid": "real_estate", "hostname": "85d76567f04f", "block_type": "data_loader", "level": "INFO", "message": "Loading data from PostgreSQL table 'public.real_estate_data'...", "timestamp": 1737060780.218883, "uuid": "a1e273cd771a4327b860464a55ab6b01"}
2025-01-16T20:53:00 {"block_run_id": 73, "block_uuid": "loads_real_estate_table", "pipeline_run_id": 11, "pipeline_schedule_id": 11, "pipeline_uuid": "real_estate", "hostname": "85d76567f04f", "block_type": "data_loader", "level": "INFO", "message": "", "timestamp": 1737060780.219123, "uuid": "2e654d863cbc4aa4920aa1e46332d104"}
2025-01-16T20:53:00 {"block_run_id": 73, "block_uuid": "loads_real_estate_table", "pipeline_run_id": 11, "pipeline_schedule_id": 11, "pipeline_uuid": "real_estate", "hostname": "85d76567f04f", "block_type": "data_loader", "level": "INFO", "message": "\u251c\u2500", "timestamp": 1737060780.219349, "uuid": "85ee48321ff3453ea7c1c53d7cf277c4"}
2025-01-16T20:53:00 {"block_run_id": 73, "block_uuid": "loads_real_estate_table", "pipeline_run_id": 11, "pipeline_schedule_id": 11, "pipeline_uuid": "real_estate", "hostname": "85d76567f04f", "block_type": "data_loader", "level": "INFO", "message": "\u2514\u2500 Loading data with query", "timestamp": 1737060780.219601, "uuid": "ca7a62c77215448aa2fae526fe3751d4"}
2025-01-16T20:53:00 {"block_run_id": 73, "block_uuid": "loads_real_estate_table", "pipeline_run_id": 11, "pipeline_schedule_id": 11, "pipeline_uuid": "real_estate", "hostname": "85d76567f04f", "block_type": "data_loader", "level": "INFO", "message": "", "timestamp": 1737060780.219811, "uuid": "e3ff15b499354a82881f1998be861961"}
2025-01-16T20:53:00 {"block_run_id": 73, "block_uuid": "loads_real_estate_table", "pipeline_run_id": 11, "pipeline_schedule_id": 11, "pipeline_uuid": "real_estate", "hostname": "85d76567f04f", "block_type": "data_loader", "level": "INFO", "message": "", "timestamp": 1737060780.220072, "uuid": "64bbdad94876457a82ebe2cb6c9f013f"}
2025-01-16T20:53:00 {"block_run_id": 73, "block_uuid": "loads_real_estate_table", "pipeline_run_id": 11, "pipeline_schedule_id": 11, "pipeline_uuid": "real_estate", "hostname": "85d76567f04f", "block_type": "data_loader", "level": "INFO", "message": "    SELECT *", "timestamp": 1737060780.220288, "uuid": "fa1eb83018464748bb1d36502232d1c8"}
2025-01-16T20:53:00 {"block_run_id": 73, "block_uuid": "loads_real_estate_table", "pipeline_run_id": 11, "pipeline_schedule_id": 11, "pipeline_uuid": "real_estate", "hostname": "85d76567f04f", "block_type": "data_loader", "level": "INFO", "message": "    FROM public.real_estate_data  -- Replace with your actual table name and schema", "timestamp": 1737060780.220485, "uuid": "e56aa829544e492f86a6c2eada304daa"}
2025-01-16T20:53:00 {"block_run_id": 73, "block_uuid": "loads_real_estate_table", "pipeline_run_id": 11, "pipeline_schedule_id": 11, "pipeline_uuid": "real_estate", "hostname": "85d76567f04f", "block_type": "data_loader", "level": "INFO", "message": "", "timestamp": 1737060780.220726, "uuid": "269c0a74a1bc4d77bd8cf99cc7f1635f"}
2025-01-16T20:53:00 {"block_run_id": 73, "block_uuid": "loads_real_estate_table", "pipeline_run_id": 11, "pipeline_schedule_id": 11, "pipeline_uuid": "real_estate", "hostname": "85d76567f04f", "block_type": "data_loader", "level": "INFO", "message": "", "timestamp": 1737060780.220975, "uuid": "680ce75f2e944927b567c38a16161bcf"}
2025-01-16T20:53:00 {"block_run_id": 73, "block_uuid": "loads_real_estate_table", "pipeline_run_id": 11, "pipeline_schedule_id": 11, "pipeline_uuid": "real_estate", "hostname": "85d76567f04f", "block_type": "data_loader", "level": "INFO", "message": "...", "timestamp": 1737060780.221214, "uuid": "90cae6d138544d019bc375823611aa74"}
2025-01-16T20:53:00 {"block_run_id": 73, "block_uuid": "loads_real_estate_table", "pipeline_run_id": 11, "pipeline_schedule_id": 11, "pipeline_uuid": "real_estate", "hostname": "85d76567f04f", "block_type": "data_loader", "level": "WARNING", "message": "Exception thrown when attempting to run <function BlockExecutor.execute.<locals>.__execute_with_retry at 0x7fcd662fbb50>, attempt 1 of 1", "timestamp": 1737060780.221726, "uuid": "0f5ac856063e4525ad96ad36c971e0fc", "error": "Traceback (most recent call last):\n  File \"/usr/local/lib/python3.10/site-packages/mage_ai/io/base.py\", line 403, in conn\n    return self._ctx\nAttributeError: 'Postgres' object has no attribute '_ctx'\n\nDuring handling of the above exception, another exception occurred:\n\nTraceback (most recent call last):\n  File \"/usr/local/lib/python3.10/site-packages/mage_ai/shared/retry.py\", line 38, in retry_func\n    return func(*args, **kwargs)\n  File \"/usr/local/lib/python3.10/site-packages/mage_ai/data_preparation/executors/block_executor.py\", line 621, in __execute_with_retry\n    return self._execute(\n  File \"/usr/local/lib/python3.10/site-packages/mage_ai/data_preparation/executors/block_executor.py\", line 1154, in _execute\n    result = self.block.execute_sync(\n  File \"/usr/local/lib/python3.10/site-packages/mage_ai/data_preparation/models/block/__init__.py\", line 1691, in execute_sync\n    return __execute()\n  File \"/usr/local/lib/python3.10/site-packages/mage_ai/data_preparation/models/block/__init__.py\", line 1668, in __execute\n    raise err\n  File \"/usr/local/lib/python3.10/site-packages/mage_ai/data_preparation/models/block/__init__.py\", line 1570, in __execute\n    output = self.execute_block(\n  File \"/usr/local/lib/python3.10/site-packages/mage_ai/data_preparation/models/block/__init__.py\", line 1910, in execute_block\n    outputs = self._execute_block(\n  File \"/usr/local/lib/python3.10/site-packages/mage_ai/data_preparation/models/block/__init__.py\", line 2073, in _execute_block\n    outputs = self.execute_block_function(\n  File \"/usr/local/lib/python3.10/site-packages/mage_ai/data_preparation/models/block/__init__.py\", line 2169, in execute_block_function\n    output = block_function_updated(*input_vars, **global_vars)\n  File \"<string>\", line 30, in load_data_from_postgres\n  File \"/usr/local/lib/python3.10/site-packages/mage_ai/io/sql.py\", line 216, in load\n    self.conn,\n  File \"/usr/local/lib/python3.10/site-packages/mage_ai/io/base.py\", line 405, in conn\n    raise ConnectionError(\nConnectionError: No connection currently open. Open a new connection to access this property.\n", "error_stack": ["  File \"/usr/local/bin/mage\", line 8, in <module>\n    sys.exit(app())\n", "  File \"/usr/local/lib/python3.10/site-packages/typer/main.py\", line 311, in __call__\n    return get_command(self)(*args, **kwargs)\n", "  File \"/usr/local/lib/python3.10/site-packages/click/core.py\", line 1130, in __call__\n    return self.main(*args, **kwargs)\n", "  File \"/usr/local/lib/python3.10/site-packages/typer/core.py\", line 778, in main\n    return _main(\n", "  File \"/usr/local/lib/python3.10/site-packages/typer/core.py\", line 216, in _main\n    rv = self.invoke(ctx)\n", "  File \"/usr/local/lib/python3.10/site-packages/click/core.py\", line 1657, in invoke\n    return _process_result(sub_ctx.command.invoke(sub_ctx))\n", "  File \"/usr/local/lib/python3.10/site-packages/click/core.py\", line 1404, in invoke\n    return ctx.invoke(self.callback, **ctx.params)\n", "  File \"/usr/local/lib/python3.10/site-packages/click/core.py\", line 760, in invoke\n    return __callback(*args, **kwargs)\n", "  File \"/usr/local/lib/python3.10/site-packages/typer/main.py\", line 683, in wrapper\n    return callback(**use_params)  # type: ignore\n", "  File \"/usr/local/lib/python3.10/site-packages/mage_ai/cli/main.py\", line 147, in start\n    start_server(\n", "  File \"/usr/local/lib/python3.10/site-packages/mage_ai/server/server.py\", line 809, in start_server\n    scheduler_manager.start_scheduler()\n", "  File \"/usr/local/lib/python3.10/site-packages/mage_ai/server/scheduler_manager.py\", line 106, in start_scheduler\n    proc.start()\n", "  File \"/usr/local/lib/python3.10/multiprocessing/process.py\", line 121, in start\n    self._popen = self._Popen(self)\n", "  File \"/usr/local/lib/python3.10/multiprocessing/context.py\", line 224, in _Popen\n    return _default_context.get_context().Process._Popen(process_obj)\n", "  File \"/usr/local/lib/python3.10/multiprocessing/context.py\", line 281, in _Popen\n    return Popen(process_obj)\n", "  File \"/usr/local/lib/python3.10/multiprocessing/popen_fork.py\", line 19, in __init__\n    self._launch(process_obj)\n", "  File \"/usr/local/lib/python3.10/multiprocessing/popen_fork.py\", line 71, in _launch\n    code = process_obj._bootstrap(parent_sentinel=child_r)\n", "  File \"/usr/local/lib/python3.10/multiprocessing/process.py\", line 314, in _bootstrap\n    self.run()\n", "  File \"/usr/local/lib/python3.10/multiprocessing/process.py\", line 108, in run\n    self._target(*self._args, **self._kwargs)\n", "  File \"/usr/local/lib/python3.10/site-packages/mage_ai/orchestration/db/process.py\", line 15, in start_session_and_run\n    results = target(*args)\n", "  File \"/usr/local/lib/python3.10/site-packages/mage_ai/server/scheduler_manager.py\", line 58, in run_scheduler\n    LoopTimeTrigger().start()\n", "  File \"/usr/local/lib/python3.10/site-packages/mage_ai/orchestration/triggers/loop_time_trigger.py\", line 14, in start\n    self.run()\n", "  File \"/usr/local/lib/python3.10/site-packages/mage_ai/orchestration/triggers/time_trigger.py\", line 11, in run\n    schedule_all()\n", "  File \"/usr/local/lib/python3.10/site-packages/mage_ai/orchestration/pipeline_scheduler_original.py\", line 1702, in schedule_all\n    PipelineScheduler(r).start()\n", "  File \"/usr/local/lib/python3.10/site-packages/mage_ai/orchestration/db/__init__.py\", line 158, in func_with_rollback\n    return func(*args, **kwargs)\n", "  File \"/usr/local/lib/python3.10/site-packages/mage_ai/orchestration/pipeline_scheduler_original.py\", line 197, in start\n    self.schedule()\n", "  File \"/usr/local/lib/python3.10/site-packages/mage_ai/orchestration/db/__init__.py\", line 158, in func_with_rollback\n    return func(*args, **kwargs)\n", "  File \"/usr/local/lib/python3.10/site-packages/mage_ai/orchestration/pipeline_scheduler_original.py\", line 333, in schedule\n    self.__schedule_blocks(block_runs)\n", "  File \"/usr/local/lib/python3.10/site-packages/mage_ai/orchestration/pipeline_scheduler_original.py\", line 640, in __schedule_blocks\n    job_manager.add_job(\n", "  File \"/usr/local/lib/python3.10/site-packages/mage_ai/orchestration/job_manager.py\", line 20, in add_job\n    self.queue.enqueue(job_id, target, *args, **kwargs)\n", "  File \"/usr/local/lib/python3.10/site-packages/mage_ai/orchestration/queue/process_queue.py\", line 121, in enqueue\n    self.start_worker_pool()\n", "  File \"/usr/local/lib/python3.10/site-packages/mage_ai/orchestration/queue/process_queue.py\", line 198, in start_worker_pool\n    self.worker_pool_proc.start()\n", "  File \"/usr/local/lib/python3.10/multiprocessing/process.py\", line 121, in start\n    self._popen = self._Popen(self)\n", "  File \"/usr/local/lib/python3.10/multiprocessing/context.py\", line 224, in _Popen\n    return _default_context.get_context().Process._Popen(process_obj)\n", "  File \"/usr/local/lib/python3.10/multiprocessing/context.py\", line 281, in _Popen\n    return Popen(process_obj)\n", "  File \"/usr/local/lib/python3.10/multiprocessing/popen_fork.py\", line 19, in __init__\n    self._launch(process_obj)\n", "  File \"/usr/local/lib/python3.10/multiprocessing/popen_fork.py\", line 71, in _launch\n    code = process_obj._bootstrap(parent_sentinel=child_r)\n", "  File \"/usr/local/lib/python3.10/multiprocessing/process.py\", line 314, in _bootstrap\n    self.run()\n", "  File \"/usr/local/lib/python3.10/multiprocessing/process.py\", line 108, in run\n    self._target(*self._args, **self._kwargs)\n", "  File \"/usr/local/lib/python3.10/site-packages/mage_ai/orchestration/queue/process_queue.py\", line 351, in poll_job_and_execute\n    worker.start()\n", "  File \"/usr/local/lib/python3.10/multiprocessing/process.py\", line 121, in start\n    self._popen = self._Popen(self)\n", "  File \"/usr/local/lib/python3.10/multiprocessing/context.py\", line 224, in _Popen\n    return _default_context.get_context().Process._Popen(process_obj)\n", "  File \"/usr/local/lib/python3.10/multiprocessing/context.py\", line 281, in _Popen\n    return Popen(process_obj)\n", "  File \"/usr/local/lib/python3.10/multiprocessing/popen_fork.py\", line 19, in __init__\n    self._launch(process_obj)\n", "  File \"/usr/local/lib/python3.10/multiprocessing/popen_fork.py\", line 71, in _launch\n    code = process_obj._bootstrap(parent_sentinel=child_r)\n", "  File \"/usr/local/lib/python3.10/multiprocessing/process.py\", line 314, in _bootstrap\n    self.run()\n", "  File \"/usr/local/lib/python3.10/site-packages/newrelic/api/background_task.py\", line 117, in wrapper\n    return wrapped(*args, **kwargs)\n", "  File \"/usr/local/lib/python3.10/site-packages/mage_ai/orchestration/queue/process_queue.py\", line 315, in run\n    start_session_and_run(args[1], *args[2], **args[3])\n", "  File \"/usr/local/lib/python3.10/site-packages/mage_ai/orchestration/db/process.py\", line 15, in start_session_and_run\n    results = target(*args)\n", "  File \"/usr/local/lib/python3.10/site-packages/mage_ai/orchestration/pipeline_scheduler_original.py\", line 1235, in run_block\n    return ExecutorFactory.get_block_executor(\n", "  File \"/usr/local/lib/python3.10/site-packages/mage_ai/data_preparation/executors/block_executor.py\", line 647, in execute\n    result = __execute_with_retry()\n", "  File \"/usr/local/lib/python3.10/site-packages/mage_ai/shared/retry.py\", line 46, in retry_func\n    logger.warning(\n", "  File \"/usr/local/lib/python3.10/site-packages/mage_ai/data_preparation/logging/logger.py\", line 39, in warning\n    self.__send_message('warning', message, **kwargs)\n", "  File \"/usr/local/lib/python3.10/site-packages/mage_ai/data_preparation/logging/logger.py\", line 65, in __send_message\n    data['error_stack'] = traceback.format_stack()\n"], "error_stacktrace": "No connection currently open. Open a new connection to access this property."}
2025-01-16T20:53:00 {"block_run_id": 73, "block_uuid": "loads_real_estate_table", "pipeline_run_id": 11, "pipeline_schedule_id": 11, "pipeline_uuid": "real_estate", "hostname": "85d76567f04f", "block_type": "data_loader", "level": "EXCEPTION", "message": "Failed to execute block loads_real_estate_table", "timestamp": 1737060780.225079, "uuid": "c5134b29b1a6417eacdf267af3218386", "error": "Traceback (most recent call last):\n  File \"/usr/local/lib/python3.10/site-packages/mage_ai/io/base.py\", line 403, in conn\n    return self._ctx\nAttributeError: 'Postgres' object has no attribute '_ctx'\n\nDuring handling of the above exception, another exception occurred:\n\nTraceback (most recent call last):\n  File \"/usr/local/lib/python3.10/site-packages/mage_ai/data_preparation/executors/block_executor.py\", line 647, in execute\n    result = __execute_with_retry()\n  File \"/usr/local/lib/python3.10/site-packages/mage_ai/shared/retry.py\", line 54, in retry_func\n    raise e\n  File \"/usr/local/lib/python3.10/site-packages/mage_ai/shared/retry.py\", line 38, in retry_func\n    return func(*args, **kwargs)\n  File \"/usr/local/lib/python3.10/site-packages/mage_ai/data_preparation/executors/block_executor.py\", line 621, in __execute_with_retry\n    return self._execute(\n  File \"/usr/local/lib/python3.10/site-packages/mage_ai/data_preparation/executors/block_executor.py\", line 1154, in _execute\n    result = self.block.execute_sync(\n  File \"/usr/local/lib/python3.10/site-packages/mage_ai/data_preparation/models/block/__init__.py\", line 1691, in execute_sync\n    return __execute()\n  File \"/usr/local/lib/python3.10/site-packages/mage_ai/data_preparation/models/block/__init__.py\", line 1668, in __execute\n    raise err\n  File \"/usr/local/lib/python3.10/site-packages/mage_ai/data_preparation/models/block/__init__.py\", line 1570, in __execute\n    output = self.execute_block(\n  File \"/usr/local/lib/python3.10/site-packages/mage_ai/data_preparation/models/block/__init__.py\", line 1910, in execute_block\n    outputs = self._execute_block(\n  File \"/usr/local/lib/python3.10/site-packages/mage_ai/data_preparation/models/block/__init__.py\", line 2073, in _execute_block\n    outputs = self.execute_block_function(\n  File \"/usr/local/lib/python3.10/site-packages/mage_ai/data_preparation/models/block/__init__.py\", line 2169, in execute_block_function\n    output = block_function_updated(*input_vars, **global_vars)\n  File \"<string>\", line 30, in load_data_from_postgres\n  File \"/usr/local/lib/python3.10/site-packages/mage_ai/io/sql.py\", line 216, in load\n    self.conn,\n  File \"/usr/local/lib/python3.10/site-packages/mage_ai/io/base.py\", line 405, in conn\n    raise ConnectionError(\nConnectionError: No connection currently open. Open a new connection to access this property.\n", "error_stack": ["  File \"/usr/local/bin/mage\", line 8, in <module>\n    sys.exit(app())\n", "  File \"/usr/local/lib/python3.10/site-packages/typer/main.py\", line 311, in __call__\n    return get_command(self)(*args, **kwargs)\n", "  File \"/usr/local/lib/python3.10/site-packages/click/core.py\", line 1130, in __call__\n    return self.main(*args, **kwargs)\n", "  File \"/usr/local/lib/python3.10/site-packages/typer/core.py\", line 778, in main\n    return _main(\n", "  File \"/usr/local/lib/python3.10/site-packages/typer/core.py\", line 216, in _main\n    rv = self.invoke(ctx)\n", "  File \"/usr/local/lib/python3.10/site-packages/click/core.py\", line 1657, in invoke\n    return _process_result(sub_ctx.command.invoke(sub_ctx))\n", "  File \"/usr/local/lib/python3.10/site-packages/click/core.py\", line 1404, in invoke\n    return ctx.invoke(self.callback, **ctx.params)\n", "  File \"/usr/local/lib/python3.10/site-packages/click/core.py\", line 760, in invoke\n    return __callback(*args, **kwargs)\n", "  File \"/usr/local/lib/python3.10/site-packages/typer/main.py\", line 683, in wrapper\n    return callback(**use_params)  # type: ignore\n", "  File \"/usr/local/lib/python3.10/site-packages/mage_ai/cli/main.py\", line 147, in start\n    start_server(\n", "  File \"/usr/local/lib/python3.10/site-packages/mage_ai/server/server.py\", line 809, in start_server\n    scheduler_manager.start_scheduler()\n", "  File \"/usr/local/lib/python3.10/site-packages/mage_ai/server/scheduler_manager.py\", line 106, in start_scheduler\n    proc.start()\n", "  File \"/usr/local/lib/python3.10/multiprocessing/process.py\", line 121, in start\n    self._popen = self._Popen(self)\n", "  File \"/usr/local/lib/python3.10/multiprocessing/context.py\", line 224, in _Popen\n    return _default_context.get_context().Process._Popen(process_obj)\n", "  File \"/usr/local/lib/python3.10/multiprocessing/context.py\", line 281, in _Popen\n    return Popen(process_obj)\n", "  File \"/usr/local/lib/python3.10/multiprocessing/popen_fork.py\", line 19, in __init__\n    self._launch(process_obj)\n", "  File \"/usr/local/lib/python3.10/multiprocessing/popen_fork.py\", line 71, in _launch\n    code = process_obj._bootstrap(parent_sentinel=child_r)\n", "  File \"/usr/local/lib/python3.10/multiprocessing/process.py\", line 314, in _bootstrap\n    self.run()\n", "  File \"/usr/local/lib/python3.10/multiprocessing/process.py\", line 108, in run\n    self._target(*self._args, **self._kwargs)\n", "  File \"/usr/local/lib/python3.10/site-packages/mage_ai/orchestration/db/process.py\", line 15, in start_session_and_run\n    results = target(*args)\n", "  File \"/usr/local/lib/python3.10/site-packages/mage_ai/server/scheduler_manager.py\", line 58, in run_scheduler\n    LoopTimeTrigger().start()\n", "  File \"/usr/local/lib/python3.10/site-packages/mage_ai/orchestration/triggers/loop_time_trigger.py\", line 14, in start\n    self.run()\n", "  File \"/usr/local/lib/python3.10/site-packages/mage_ai/orchestration/triggers/time_trigger.py\", line 11, in run\n    schedule_all()\n", "  File \"/usr/local/lib/python3.10/site-packages/mage_ai/orchestration/pipeline_scheduler_original.py\", line 1702, in schedule_all\n    PipelineScheduler(r).start()\n", "  File \"/usr/local/lib/python3.10/site-packages/mage_ai/orchestration/db/__init__.py\", line 158, in func_with_rollback\n    return func(*args, **kwargs)\n", "  File \"/usr/local/lib/python3.10/site-packages/mage_ai/orchestration/pipeline_scheduler_original.py\", line 197, in start\n    self.schedule()\n", "  File \"/usr/local/lib/python3.10/site-packages/mage_ai/orchestration/db/__init__.py\", line 158, in func_with_rollback\n    return func(*args, **kwargs)\n", "  File \"/usr/local/lib/python3.10/site-packages/mage_ai/orchestration/pipeline_scheduler_original.py\", line 333, in schedule\n    self.__schedule_blocks(block_runs)\n", "  File \"/usr/local/lib/python3.10/site-packages/mage_ai/orchestration/pipeline_scheduler_original.py\", line 640, in __schedule_blocks\n    job_manager.add_job(\n", "  File \"/usr/local/lib/python3.10/site-packages/mage_ai/orchestration/job_manager.py\", line 20, in add_job\n    self.queue.enqueue(job_id, target, *args, **kwargs)\n", "  File \"/usr/local/lib/python3.10/site-packages/mage_ai/orchestration/queue/process_queue.py\", line 121, in enqueue\n    self.start_worker_pool()\n", "  File \"/usr/local/lib/python3.10/site-packages/mage_ai/orchestration/queue/process_queue.py\", line 198, in start_worker_pool\n    self.worker_pool_proc.start()\n", "  File \"/usr/local/lib/python3.10/multiprocessing/process.py\", line 121, in start\n    self._popen = self._Popen(self)\n", "  File \"/usr/local/lib/python3.10/multiprocessing/context.py\", line 224, in _Popen\n    return _default_context.get_context().Process._Popen(process_obj)\n", "  File \"/usr/local/lib/python3.10/multiprocessing/context.py\", line 281, in _Popen\n    return Popen(process_obj)\n", "  File \"/usr/local/lib/python3.10/multiprocessing/popen_fork.py\", line 19, in __init__\n    self._launch(process_obj)\n", "  File \"/usr/local/lib/python3.10/multiprocessing/popen_fork.py\", line 71, in _launch\n    code = process_obj._bootstrap(parent_sentinel=child_r)\n", "  File \"/usr/local/lib/python3.10/multiprocessing/process.py\", line 314, in _bootstrap\n    self.run()\n", "  File \"/usr/local/lib/python3.10/multiprocessing/process.py\", line 108, in run\n    self._target(*self._args, **self._kwargs)\n", "  File \"/usr/local/lib/python3.10/site-packages/mage_ai/orchestration/queue/process_queue.py\", line 351, in poll_job_and_execute\n    worker.start()\n", "  File \"/usr/local/lib/python3.10/multiprocessing/process.py\", line 121, in start\n    self._popen = self._Popen(self)\n", "  File \"/usr/local/lib/python3.10/multiprocessing/context.py\", line 224, in _Popen\n    return _default_context.get_context().Process._Popen(process_obj)\n", "  File \"/usr/local/lib/python3.10/multiprocessing/context.py\", line 281, in _Popen\n    return Popen(process_obj)\n", "  File \"/usr/local/lib/python3.10/multiprocessing/popen_fork.py\", line 19, in __init__\n    self._launch(process_obj)\n", "  File \"/usr/local/lib/python3.10/multiprocessing/popen_fork.py\", line 71, in _launch\n    code = process_obj._bootstrap(parent_sentinel=child_r)\n", "  File \"/usr/local/lib/python3.10/multiprocessing/process.py\", line 314, in _bootstrap\n    self.run()\n", "  File \"/usr/local/lib/python3.10/site-packages/newrelic/api/background_task.py\", line 117, in wrapper\n    return wrapped(*args, **kwargs)\n", "  File \"/usr/local/lib/python3.10/site-packages/mage_ai/orchestration/queue/process_queue.py\", line 315, in run\n    start_session_and_run(args[1], *args[2], **args[3])\n", "  File \"/usr/local/lib/python3.10/site-packages/mage_ai/orchestration/db/process.py\", line 15, in start_session_and_run\n    results = target(*args)\n", "  File \"/usr/local/lib/python3.10/site-packages/mage_ai/orchestration/pipeline_scheduler_original.py\", line 1235, in run_block\n    return ExecutorFactory.get_block_executor(\n", "  File \"/usr/local/lib/python3.10/site-packages/mage_ai/data_preparation/executors/block_executor.py\", line 649, in execute\n    self.logger.exception(\n", "  File \"/usr/local/lib/python3.10/site-packages/mage_ai/data_preparation/logging/logger.py\", line 30, in exception\n    self.__send_message('exception', message, **kwargs)\n", "  File \"/usr/local/lib/python3.10/site-packages/mage_ai/data_preparation/logging/logger.py\", line 65, in __send_message\n    data['error_stack'] = traceback.format_stack()\n"], "error_stacktrace": "No connection currently open. Open a new connection to access this property."}
Traceback (most recent call last):
  File "/usr/local/lib/python3.10/site-packages/mage_ai/io/base.py", line 403, in conn
    return self._ctx
AttributeError: 'Postgres' object has no attribute '_ctx'

During handling of the above exception, another exception occurred:

Traceback (most recent call last):
  File "/usr/local/lib/python3.10/site-packages/mage_ai/data_preparation/executors/block_executor.py", line 647, in execute
    result = __execute_with_retry()
  File "/usr/local/lib/python3.10/site-packages/mage_ai/shared/retry.py", line 54, in retry_func
    raise e
  File "/usr/local/lib/python3.10/site-packages/mage_ai/shared/retry.py", line 38, in retry_func
    return func(*args, **kwargs)
  File "/usr/local/lib/python3.10/site-packages/mage_ai/data_preparation/executors/block_executor.py", line 621, in __execute_with_retry
    return self._execute(
  File "/usr/local/lib/python3.10/site-packages/mage_ai/data_preparation/executors/block_executor.py", line 1154, in _execute
    result = self.block.execute_sync(
  File "/usr/local/lib/python3.10/site-packages/mage_ai/data_preparation/models/block/__init__.py", line 1691, in execute_sync
    return __execute()
  File "/usr/local/lib/python3.10/site-packages/mage_ai/data_preparation/models/block/__init__.py", line 1668, in __execute
    raise err
  File "/usr/local/lib/python3.10/site-packages/mage_ai/data_preparation/models/block/__init__.py", line 1570, in __execute
    output = self.execute_block(
  File "/usr/local/lib/python3.10/site-packages/mage_ai/data_preparation/models/block/__init__.py", line 1910, in execute_block
    outputs = self._execute_block(
  File "/usr/local/lib/python3.10/site-packages/mage_ai/data_preparation/models/block/__init__.py", line 2073, in _execute_block
    outputs = self.execute_block_function(
  File "/usr/local/lib/python3.10/site-packages/mage_ai/data_preparation/models/block/__init__.py", line 2169, in execute_block_function
    output = block_function_updated(*input_vars, **global_vars)
  File "<string>", line 30, in load_data_from_postgres
  File "/usr/local/lib/python3.10/site-packages/mage_ai/io/sql.py", line 216, in load
    self.conn,
  File "/usr/local/lib/python3.10/site-packages/mage_ai/io/base.py", line 405, in conn
    raise ConnectionError(
ConnectionError: No connection currently open. Open a new connection to access this property.
